Workbook

Sheet dharm_ds
A1: Comments | B1: neutral | C1: hate_speech | D1: threatning | E1: offensive | F1: harassment
A2: Even if Harke says 2+2=4, Xetry bahun and ghantey still say "no no, that's wrong." | C2: 1
A3: Pratiksha Neyong Limbu Ani eai rai limbu lai matra na ramro lagne hora | C3: 1
A4: Rozey Malla Thakuri ani Timaru aru jattle Rai limbu hernu nasakeko chy kin?? Harka ko birodh garne fery aru jat ko matr xannn tw ....sahi kura gardaa pni birodh garx | C4: 1
A5: R*** haru | C5: 1
A6: Madhesey ko batho talk..Marya madhesey ley 7 jana jimdo nepal sakxa | C6: 1
A7: Gara gara birod kei napdenou sab rai limbu matra hun harke ka senapati pthayexa | C7: 1
A8: Bijaya Adhikari ma chikne tapare goru randika xora | C8: 1
A9: Hasayo bahun le | C9: 1
A10: Rsp party yedi Balenle sath suport nagaridiyera pahilekai jasto vaueko vaye...yo chetri Bahunle tei Kp lai nai vagwan manera ghu chatdai hintyo holla..ramro lai ramro vanunasknunai chetri bahunko mul biami ho. | C10: 1
A11: teu ta dinunai parxni dhoti sarakarle | C11: 1
A12: yesto khate religion le garda ho Nepal bigreko lado jasto unity is diversity India huna laxa Nepal pani | C12: 1
A13: Nepal does not have the status to become a part of India. Nepal is a part of Bihar. Pataliputra | C13: 1
... A1158: Tyo khate lai kasai le naak bhanchne gari hanna janta hern chahanchhan. | C1158: 1
A1159: teti pdeko xa harke le? | E1159: 1
A1160: Kam xaina teniharu ko | E1160: 1
A1161: E bideshi dalal ko sarkarlai sachet nepali le desh nikala garnu parxa | E1161: 1
A1162: kadal ayusha mahakali bechua KO Santan xa kina na garosh | E1162: 1
A1163: Kam payea j hoss berojgarr haru ley.. | E1163: 1
A1164: Beroj gari haru ko kam nai k xa ra vanya | E1164: 1
A1165: Sab kp ko xaura haru hun | E1165: 1
A1166: Ekata Adhikari bolna payo vandai ma kehi nasochi bolne ho ta | E1166: 1
A1167: Kursi uchalne bani kaile nahatne vo neta haru ko | E1167: 1
A1168: Yasto haru laii jitayasi yasataiii ho | E1168: 1
A1169: Manpower daley lai sabhamukh banayesi aba yestai hunchaa. | E1169: 1
A1170: Nepal naii India ko ho k madachot kina kura nabujeko | E1170: 1
... A1600: Tero nari pani gatilo ta hoines ramro ra spashta bolne aaphno poi khayaraalis. (x2) | E1600: 1
A1601: Yuba vaye c 2/4 mukka ek arka lai hana han ta hunu parxa | D1601: 1
A1602: Nepal Police mama vaata hannu ta | D1602: 1
A1603: k hereko Debre haat ley deyna | D1603: 1
A1604: Kurchi uchalne kun party Ko rayexin teskai tauko ma bajaunu parne | D1604: 1
A1605: Sab Lai. Bhata han sarkar | D1605: 1
A1606: Haa haneya jeu haru murdabad | D1606: 1
A1607: Bhata charge napuge KO hau ek dui bhata lagam na yinihru laii ani line ma aaucha.. | D1607: 1
A1608: Pratipakshya lai kich out handim | D1608: 1
A1609: Ini ma chikne haru ko Chaak ma MDH ko rato khursani dalerw bhagaunu parxa | D1609: 1
A1610: 1 hapta lai dose iniharulai | D1610: 1
A1611: Yo sab ko chhala kadnu parxa ani sudhrinxan | D1611: 1
A1612: Chak ma daam basni gari thok saleharu lai | D1612: 1
... A1715: Neta ra balatkari ra ghuskhori lai mareu bhane timi haru sath chha nepali janta ko. | D1715: 1
...

Sheet nirab_ds
A1: Comments | B1: neutral | C1: hate_speech | D1: threatning | E1: offensive | F1: harassment

Sheet sherma_ds
A1: Comment (Clean Romanized Nepali) | B1: Neutral | C1: Hate Speech | D1: Threatening | E1: Offensive | F1: Harassment
A2: gire chor kuti kuti kuti gire muge chor | B2: 0 | C2: 1 | D2: 0 | E2: 0 | F2: 0
A3: jabo matra khate khate hoss ko lagi jhole hoss kunai ko manxe laxman ko ko recpect hainas dhotiko chora hoss | B3: 0 | C3: 1 | D3: 0 | E3: 0 | F3: 0
A4: Torpey muji boli | B4: 0 | C4: 0 | D4: 0 | E4: 1 | F4: 0
A5: lado kha mc khatay lado kha randiko choroo haru randiko gardaaa mc sabai ko badnam lado jastoo | B5: 0 | C5: 0 | D5: 0 | E5: 0 | F5: 1
A6: tudikhel jhundaunu parcha | B6: 0 | C6: 0 | D6: 1 | E6: 0 | F6: 0
A7: testo hunxa mugi Malai tha xaina | B7: 0 | C7: 0 | D7: 0 | E7: 1 | F7: 0
A8: tyo bechuwa lai xai tetikai chodeko mula yesto gareko vhaye katera faldinthiyo muji haru vhede vhayo yesto dalal lai chodekoma bahini dherai jhuto boleko jasto pani laagyo | B8: 0 | C8: 0 | D8: 1 | E8: 0 | F8: 0
A9: ko choro sapkota ko muji futera janmecha muji chakka | B9: 0 | C9: 0 | D9: 0 | E9: 0 | F9: 1
A10: yeslai karbahi hunu parcha ko bhasa kasari vayo ko chorni ajha desh chalauna deu vancha yeslai kasari desh chalauna budi bhai sakyo chitai marcha hariyo kakro rabita dhungana jaa gayera maar | B10: 0 | C10: 0 | D10: 1 | E10: 0 | F10: 0
A11: lai xatima goli hannu parne aatanlari sangatan lai garos chor | B11: 0 | C11: 0 | D11: 1 | E11: 0 | F11: 0
A12: jashle mcc tyo sabai desh testalai desh nikala garnu | B12: 0 | C12: 1 | D12: 0 | E12: 0 | F12: 0
A13: lai tira lakhet sarkar modi ko dhoyer khanxe | B13: 0 | C13: 1 | D13: 0 | E13: 0 | F13: 0
... A5775: ronit dhmla lai kehi pni thah xain | B5775: 0 | C5775: 0 | D5775: 0 | E5775: 1 | F5775: 0

Sheet ds_overview
B10: Nirab | D10: Sherma | F10: Dharm | H10: Overall | K10: Posts
B11: Class | C11: Count | D11: Class | E11: Count | F11: Class | G11: Count | H11: Class | I11: Count | K11: Collaborator | L11: Nirab | O11: Sherma | R11: Dharm
B12: neutral | C12: =COUNTIF(nirab_ds!B:B, 1) -> 0 | D12: neutral | E12: =COUNTIF(sherma_ds!B:B, 1) -> 3803 | F12: neutral | G12: =COUNTIF(dharm_ds!B:B, 1) -> 2099 | H12: neutral | I12: =Table4[[#This Row],[Count]]+Table5[[#This Row],[Count]]+Table6[[#This Row],[Count]] -> 5902 | L12: URLs
B13: hate_speech | C13: =COUNTIF(nirab_ds!C:C, 1) -> 0 | D13: hate_speech | E13: =COUNTIF(sherma_ds!C:C, 1) -> 74 | F13: hate_speech | G13: =COUNTIF(dharm_ds!C:C, 1) -> 1157 | H13: hate_speech | I13: =Table4[[#This Row],[Count]]+Table5[[#This Row],[Count]]+Table6[[#This Row],[Count]] -> 1231 | K13: Plateforms | L13: Facebook | M13: Instagram | N13: Youtube | O13: Facebook | P13: Instagram | Q13: Youtube | R13: Facebook | S13: Instagram | T13: Youtube
B14: threatning | C14: =COUNTIF(nirab_ds!D:D, 1) -> 0 | D14: threatning | E14: =COUNTIF(sherma_ds!D:D, 1) -> 70 | F14: threatning | G14: =COUNTIF(dharm_ds!D:D, 1) -> 115 | H14: threatning | I14: =Table4[[#This Row],[Count]]+Table5[[#This Row],[Count]]+Table6[[#This Row],[Count]] -> 185
B15: offensive | C15: =COUNTIF(nirab_ds!E:E, 1) -> 0 | D15: offensive | E15: =COUNTIF(sherma_ds!E:E, 1) -> 1708 | F15: offensive | G15: =COUNTIF(dharm_ds!E:E, 1) -> 442 | H15: offensive | I15: =Table4[[#This Row],[Count]]+Table5[[#This Row],[Count]]+Table6[[#This Row],[Count]] -> 2150 | R15: https://www.facebook.com/share/p/18JfnaJorD/
B16: harassment | C16: =COUNTIF(nirab_ds!F:F, 1) -> 0 | D16: harassment | E16: =COUNTIF(sherma_ds!F:F, 1) -> 119 | F16: harassment | G16: =COUNTIF(dharm_ds!F:F, 1) -> 127 | H16: harassment | I16: =Table4[[#This Row],[Count]]+Table5[[#This Row],[Count]]+Table6[[#This Row],[Count]] -> 246 | R16: https://www.facebook.com/share/p/1Ewe6gMpxb/
B17: Total | C17: =SUM(C12:C16) -> 0 | D17: Total | E17: =SUM(E12:E16) -> 5774 | F17: Total | G17: =SUM(G12:G16) -> 3940 | H17: Total | I17: =Table4[[#This Row],[Count]]+Table5[[#This Row],[Count]]+Table6[[#This Row],[Count]] -> 9714 | R17: https://www.facebook.com/share/p/1U5cDLipti/
R18: https://www.facebook.com/permalink.php?story_fbid=pfbid0MansG4R3pT8pmFiJND8KrJ4urWFA2EXu7UVroFtBm2zzXDcHYwF1vecdBfcaWe7kl&id=100057352183960&rdid=2lXGJ0XoIGhAR81A#
S19: https://www.instagram.com/p/DamlXxJNEbh/
S20: https://www.instagram.com/p/DZcPCtnEf7g/
S21: https://www.instagram.com/p/DYyC17yoiB3/
S22: https://www.instagram.com/p/DaVCh2IMqDR/
S23: https://www.instagram.com/p/DaVCh2IMqDR/
S24: https://www.instagram.com/p/DXJAWkXR-xZ/
S25: https://www.instagram.com/p/DaZLr0_o4g5/
S26: https://www.instagram.com/p/DZ9mr9cPyu1/
S27: https://www.instagram.com/p/DaSC741ouVR/
S28: https://www.instagram.com/p/DaHt0J8Dd8L/
S29: https://www.instagram.com/p/Dacc1vUE_20/
S30: https://www.instagram.com/p/DaCbGhkgdLm/
... S33: https://www.instagram.com/p/DamxXjStJ7j/

Sheet litreture_review
A1: Paper # | B1: Citation / Title | C1: Task Definition / Classification Type | D1: Data Scout: Data Source & Language Type | E1: Data Scout: Dataset Size & Splitting Strategy | F1: Linguist: Preprocessing Pipeline & Text Cleaning | G1: Linguist: Core Methodology & Rules | H1: Architect: Feature Engineering & Models | I1: Performance Metrics | J1: Baseline Comparisons | K1: Gaps / Limitations to Exploit
A2: 1 | B2: Aspect based abusive sentiment detection in Nepali social media texts | C2: Target Aspect-based Sentiment Analysis (TABSA) split into two distinct sub-tasks: Aspect Term Extraction and Sentiment Classification. | D2: Social media platforms (YouTube, Facebook, Instagram, etc.). | E2: Dataset Size (NepSA Corpus): Total Volume: 3,068 comments collected from 37 different YouTube videos across 9 channels. Length Constraint: Filtered to sentences containing at least 1 Devanagari character and structured between 5 to 50 words. Tagged Entities: Contains 2,327 Person, 432 Location, 300 Organization, and 1,235 Miscellaneous target spans. Splitting Strategy: 80% Training / 10% Testing / 10% Development (Dev) set split. Evaluation is validated using a standard 5-fold cross-validation workflow for both sub-tasks. Inter-annotator reliability was built by double-annotating a random 15% subset of the corpus using the BRAT annotation tool. | F2: Data was collected from Wikipedia and the National Corpus (books, magazines, and online news portals) to ensure negligible error rates during benchmark prep. | G2: Annotation Framework: Supervised manual annotation using strict translation schemas matching the CoNLL 2003 guidelines for Named Entities. Entity-Aspect Relationship Rule: Annotators had to identify explicit phrase-level dependencies. Instances were split into Single-targeted (one aspect linked to one entity), Multi-targeted (one aspect linked to multiple entities), or Untargeted (abusive/sentiment phrases with no direct entity target). Agreement Calibration: Achieved a pair-wise inter-annotator F1-score of 0.703 for exact word matching across all targets and aspects. Polarity identification achieved a mean F1-score of 0.602. | H2: Aspect Term Extraction: Multilingual BERT (mBERT) model. Sentiment Classification Task: Bidirectional Long Short-Term Memory (BiLSTM) network. | I2: Aspect Term Extraction: 57% score. Sentiment Classification: 81% score. | J2: Embedding Significance: Concatenating the text embeddings with target aspect terms significantly boosted classification scores across all architectures (e.g., BiLSTM F1 increased from 80.50% to 81.60%). Multilingual vs. Monolingual: Incorporating multilingual FastText (Wikipedia + OSCAR) outperformed monolingual models on sequence labeling, proving that out-of-vocabulary English/Romanized tokens require multi-source pre-training. Model Hierarchy: Unlike typical SOTA tasks where pure Transformers dominate, the standard BiLSTM network out-performed fine-tuned mBERT on sentiment classification in this domain. This demonstrates that localized sequence ordering matches conversational Nepali constraints better than generalized pre-trained multilingual embeddings. | K2: Embedding Train-Test Mismatch: The FastText and mBERT embeddings were pre-trained on clean, formal textual sources (Wikipedia, books, news portals). Consequently, they struggled heavily with spelling variations, intentional grammatical errors, and transliterated phrasing common to YouTube. Training domain-specific embeddings directly on noisy social media text remains a critical gap. Subjective Noun-Phrase Boundary Disagreements: The aspect extraction task scored low (F1 of ~57%) because annotators struggled to consistently isolate phrase boundaries for highly ambiguous categories like Violence and Feedback. Sarcasm and Out-of-Scope Omission: While Sarcasm (166 sentences) and Out-of-Scope (934 sentences) were annotated at a coarse level, they were completely excluded from the fine-grained sequence-labeling experiments. Missing Feature Signals: The pipeline left out potentially valuable structural components such as Part-of-Speech (POS) tags and LASER (Language-Agnostic Sentence Embeddings), leaving an opening for future optimization.
A3: 2 | B3: Hate Speech Detection and Classification in Devanagari Nepali and English YouTube Comments | C3: Multilingual hate speech detection and classification. Nepali labels (5 categories): General Positive, General Negative, Profanity, Violence, Feedback. English labels (3 categories): Hate Speech, Offensive, Neither. | D3: Multilingual (Devanagari Nepali and English text). Extracted from Nepali News and Politics YouTube videos, alongside an English Twitter dataset. | E3: Nepali Corpus: Initial pull of 3,068 and 2,719 comments + an intentional addition of 120 comments targeting low-frequency abuse blocks. Final cleaned and de-duplicated total = 5,907 comments. English Corpus: 24,783 tweets. Splitting strategy not explicitly specified in the notes. | F3: Nepali: Unicode normalization to NFC form, stripping zero-width characters/non-spacing marks, punctuation canonicalization, mapping Devanagari digits to ASCII, and parsing whitespace boundaries. English: Lowercasing, removal of punctuation, URLs, emojis, repeating characters, and row deduplication. | G3: Sequential routing architecture containing three stages: (1) Data retrieval, (2) Language detection, and (3) Language-specific classification. An integrated Language Detection Module directs traffic to either a Devanagari or English classifier pathway. | H3: Nepali Classifier: Fine-tuned transformer-based models (specifically MuRIL). English Classifier: BERT-base-uncased model. | I3: Nepali (MuRIL): $F_1$-score of 0.6747.English (BERT-base-uncased): $F_1$-score of 0.8678. | J3: Evaluated performance trade-offs of multiple transformer-based systems across low-resource multilingual context limits. | K3: The system explicitly excludes Romanized or code-mixed/mixed-script Nepali variants. Additionally, the size of the Nepali training data is structurally small when compared directly to the English corpora. Future recommendations point to adding data augmentation or exploring instruction-tuned large models.
A4: 3 | B4: Offensive Language Detection in Nepali Social Media (Niraula et al., 2021) | C4: Supervised offensive language detection split into binary classification (Offensive vs. Non-Offensive) and fine-grained multi-class classification across specific categories (e.g., Sexist, Racist, Insult, Profanity). | D4: Multi-platform user comments extracted from Facebook, Twitter, YouTube, and various online Blogs. The text features low-resource Nepali language scripts with significant user-generated noise. | E4: A total of 7,462 human-annotated records. The dataset was randomly split into an 80% training set (5,798 records) and a 20% testing set (1,450 records). | F4: Implemented two core script normalization strategies: Prep_Dir (Dirghikaran): Normalizes common spelling variations in vowels (e.g., matching instances of long 'ee' and short 'i' variants). Prep_Rom (Romanization): Transliterates the native Devanagari script text into Roman characters to bypass script layout variances. | G4: Evaluated the performance impact of character-level vs. word-level boundaries. The text was broken down into character trigrams as well as word unigrams and bigrams to check which handles grammatical noise better. | H4: Traditional Classifiers: Logistic Regression (LR), Support Vector Machines (SVM), and Random Forest (RF) combined with TF-IDF vectorization. Deep Learning Classifiers: Multilingual BERT (M-BERT) token embeddings | I4: Random Forest (Top Performer): Achieved the highest overall offensive $F_1$-score of 0.73. Multilingual BERT: Performed poorly, achieving a much lower offensive $F_1$-score of 0.59. Character-level trigrams vastly outperformed word-level features across all classical models. | J4: he paper establishes the first comprehensive baseline benchmarking dataset for offensive language detection in Nepali social media, comparing classical text engineering approaches directly against modern transformer frameworks. | K4: Severe Class Imbalance: Highly skewed data distribution led to abysmal performance on minority categories; for instance, the model failed completely on the "Sexist" target class, yielding an $F_1$-score of just 0.01. Domain Mismatch: Pre-trained models like M-BERT underperformed because they were trained on structured Nepali Wikipedia text rather than noisy, slang-heavy social media comments. Semantic Blindness: The system is unable to resolve contextual double-meanings or sarcasm (e.g., failing to differentiate literal animal references from contextual insults)
A5: 4 | B5: NEPTUN: Normalization for Romanized Nepali Sentiment Analysis (Chaudhary et al., 2025) | C5: Multiclass sentiment analysis classifying user opinions into three distinct polarities: Positive, Negative, or Neutral. | D5: User-generated e-commerce product reviews extracted from the Daraz platform, featuring informal, code-mixed Romanized Nepali and English text. | E5: Main Corpus: Expanded from an initial collection of 34,438 reviews down to 16,076 valid, cleaned, and labeled reviews. Reference Dictionary: A frequency-based vocabulary list containing 240,726 words derived from 39,000 cleaned Nepali Wikipedia articles. Evaluation Gold Standard: 1,000 manually mapped Romanized-to-Devanagari words annotated by three native speakers. Splitting: Randomly partitioned into an 80% training subset and a 20% testing subset. | F5: RegEx-based removal of URLs, excessive punctuation, and special characters. Sentiment-bearing emojis are explicitly replaced with textual tags (positive emoji / negative emoji). Text is lowercased and tokenized using NLTK's word tokenizer. Standard English and Nepali stop words are removed, strictly preserving critical negation terms (e.g., not, don't). | G5: Implements the novel NEPTUN normalization pipeline to resolve spelling discrepancies. It intercepts text blocks via a WordNet English dictionary to isolate and preserve English words while forwarding unrecognized strings as Romanized Nepali variants. Candidate spellings undergo character-level TF-IDF vectorization (bigrams to four-grams) and are validated against the custom Devanagari Wikipedia frequency corpus using Cosine similarity. Verified terms are then back-transliterated into the most statistically frequent Romanized root form. | H5: Traditional Classifiers: Logistic Regression (LR), Bernoulli Naive Bayes (BernoulliNB), and K-Nearest Neighbors (KNN) utilizing unigram and bigram TF-IDF representations. Deep Learning Framework: Pre-trained BERT models operating on top of dense contextual embeddings. | I5: Phonetic Accuracy: NEPTUN achieved a standalone alignment accuracy of 73.00% on the gold standard word pair set. Sentiment Accuracies (NEPTUN Preprocessing vs. Standard Preprocessing): BERT: 87.56% (NP) vs. 87.31% (SP) — Highest Performer. Logistic Regression: 83.41% (NP) vs. 83.23% (SP). K-Neighbors Classifier: 81.41% (NP) vs. 80.93% (SP). BernoulliNB: 81.26% (NP) vs. 81.30% (SP). | J5: The pipeline's phonetic accuracy (73.00%) was compared directly against traditional English-centric phonetic indexing frameworks, outperforming both Soundex (52.58%) and Double Metaphone (65.00%). Upstream sentiment performance was benchmarked by comparing NEPTUN Preprocessing (NP) side-by-side with Standard Preprocessing (SP) across all four classifiers. | K5: Limited Lexicon Bounds: Lacks a truly comprehensive, native computational Nepali dictionary dictionary asset, leading to valid localized terms (e.g., bikash) occasionally getting dropped during the validation phase. Variant Combinatorial Explosion: Long or heavily agglutinated compound phrase constructions (e.g., hajuuraaharuulee) generate an overwhelming number of potential phonetic mutations, causing high computational overhead and dropping precision. Phonetic Ambiguity Collisions: High risk of misclassification on closely sounding minimal vowel pairs (e.g., xoina vs. xaina) if phonetic maps are applied too broadly. Discourse Blind Spots: The model regularly catches false positives on complex sentence patterns containing mixed sentiments, contrastive connectives (e.g., but, tara), or trailing semantic negations.
A6: 5 | B6: Sentiment analysis of Nepali social media text with a hybrid deep learning model (Sitoula et al., 2025). | C6: Multiclass sentiment analysis classifying text into three distinct emotional categories: Positive, Negative, or Neutral. | D6: User-generated social media text written in the Nepali language, consisting of tweets and video comments reflecting public opinions across diverse domains. | E6: Evaluated across three diverse datasets: Dataset-1 (D1 / NepCOV19Tweets): 33,247 tweets collected during the COVID-19 pandemic (14,957 positive, 13,546 negative, 4,744 neutral). Dataset-2 (D2 / NepaliNLP-SA): 7,991 YouTube comments covering financial, political, and public debates (3,662 positive, 2,398 negative, 1,931 neutral). Dataset-3 (D3 / NAET): 4,445 tweets focusing on anti-establishment election discourse (927 positive, 1,156 negative, 2,169 neutral). | F6: Cleaning steps include the automated removal of hashtags, URLs, and special characters. Text tokenization is handled via a built-in Hugging Face tokenizer to map Nepali words into sub-word tokens and token IDs suitable for transformer processing. | G6: Combines global context comprehension with local spatial/semantic feature extraction. Contextual token embeddings are extracted from the final hidden layer of a pre-trained XLM-RoBERTa base model and document-level features are derived via mean pooling. Concurrently, the embedding matrix is fed into a 1D convolutional layer with a small kernel size ($k=3$) to extract overlapping trigram features, which are then downsampled using Global Max Pooling (GMP) to isolate key local semantic patterns. | H6: Proposed Hybrid Model: XLM-RoBERTa fused with a 1D Convolutional module (256 filters, kernel size 3, ReLU activation), integrated into a feature fusion layer that concatenates the pooled outputs before passing them into a dense layer (64 units, ReLU), a dropout layer (0.3), and a final Softmax classification layer. Baseline Cohorts: Traditional ML models (Random Forest, SVM, Logistic Regression, KNN) trained on Bag-of-Words/TF-IDF features; Deep Learning architectures (Standard LSTM, Bi-LSTM, CNN, Multi-Channel CNN); and fine-tuned pre-trained language models (BERT, XLM-R, NepaliBERT, DistilBERT, mbert-Nepali-NER). | I6: Overall Classification Accuracies (Ours): 74.77% on D1, 79.52% on D2, and 55.82% on D3 (Highest across all evaluated cohorts). Overall Macro Metrics (Ours): D1: Precision: 0.6877, Recall: 0.7041, F1-score: 0.6959. D2: Precision: 0.7782, Recall: 0.7862, F1-score: 0.7822. D3: Precision: 0.5135, Recall: 0.5075, F1-score: 0.5105. Class-wise F1-scores (Ours): D1: Negative: 76.62%, Neutral: 52.17%, Positive: 78.03%. D2: Negative: 68.08%, Neutral: 78.48%, Positive: 87.27%. D3: Negative: 44.82%, Neutral: 68.70%, Positive: 38.81%. | J6: Outperformed traditional ML models, where Random Forest achieved the best baseline accuracies of 68.0% (D1), 69.3% (D2), and 53.8% (D3). Surpassed standard DL pipelines (CNN accuracy: 71.10% on D1, 71.98% on D2, 52.29% on D3) and standalone fine-tuned large PLMs like NepaliBERT (Accuracy: 73.79% on D1, 77.80% on D2, 54.99% on D3). It also established a new state-of-the-art benchmark, outperforming previous specialized architectures on D1 (Shahi et al., 2022 at 72.10% accuracy) and D3 (DistilBERT at 0.4670 F1-score). | K6: Unimodal Constraint: Relies exclusively on textual features to determine public sentiment, completely ignoring vital multimedia data elements. Deployment and Computational Overhead: The underlying heavy PLM backbone introduces high computational costs, posing strict deployment barriers in low-resource environments or edge systems lacking optimizations like quantization or pruning. Neutral Class Distortions: Demonstrates high performance variability and lower classification accuracy on highly imbalanced datasets when isolating neutral expressions (e.g., F1-score of 52.17% on D1).
A7: 6 | B7: Hate Speech Detection in Nepali Social Media: A Comparative Analysis of Machine Learning and Transformer-based Approaches (Shakya et al., 2025). | C7: Binary classification identifying text as either Hate or Non-Hate speech. | D7: User-generated social media text from Twitter (tweets) written in both Devanagari script and Romanized Nepali, demonstrating a high frequency of code-mixing common in public online discourse. | E7: Evaluated on the NEHATE corpus comprising a total of 13,505 annotated samples (8,778 non-hate, 4,727 hate) collected from Nepal's 2022 municipal election discourse. The corpus was partitioned using an 80-20 stratified train-test split, yielding 10,804 training samples and 2,701 testing samples. | F7: A multi-step normalization pipeline that handles raw inputs by sequentially executing: (1) URL and @mention removal, (2) hashtag processing to strip the '#' symbol while retaining the text tokens, (3) special character and emoji removal, (4) Devanagari Unicode character normalization, (5) whitespace standardization, and (6) converting Romanized text entirely to lowercase. | G7: Combines data-driven statistical features with explicit domain-specific knowledge by checking inputs against a curated lexicon of 1,077 offensive words. The lexicon maps terms to discrete semantic classes—Politics (115 terms), Race (77), Vulgar (50), Disability (37), and Gender (15)—and maps severity rankings from 1 (mild) to 5 (severe), containing 159 taboo and 158 severely offensive items. Crucially, the lexicon is not used for training data; it acts as a secondary feature engineering layer to compute signal vectors alongside character patterns. | H7: Traditional ML Representation: Extracted character-level n-grams ($n=2\text{ to }5$) with TF-IDF weighting, stacked horizontally with extracted lexicon attribute vectors (offensive term counts, max/average offensiveness scores, ratio of offensive terms, taboo counts, and category-specific semantic indicators) to form a unified feature matrix. Evaluated ML Classifiers: Random Forest Classifier (100 trees, Gini impurity), Naive Bayes (alpha smoothing of 0.1), and Gradient Boosting (100 boosting stages, learning rate 0.1, max depth 5). Fine-tuned Transformer Cohorts: Multilingual BERT (mBERT), XLM-RoBERTa, and MuRIL (Multilingual Representations for Indian Languages) fine-tuned with a learning rate of $2\times10^{-5}$, a batch size of 16, a sequence length of 128, a dropout rate of 0.1, and an Adam optimizer tracking binary cross-entropy over 5 epochs. | I7: Traditional ML Performance (TF-IDF + Lexicon): Random Forest: Accuracy: 0.852, F1-score: 0.847, AUC-ROC: 0.912. Gradient Boosting: Accuracy: 0.839, F1-score: 0.835, AUC-ROC: 0.901. Naive Bayes: Accuracy: 0.824, F1-score: 0.821, AUC-ROC: 0.889. Fine-tuned Transformer Performance: MuRIL: Accuracy: 0.867, F1-score: 0.863, AUC-ROC: 0.908. mBERT: Accuracy: 0.851, F1-score: 0.852, AUC-ROC: 0.914. XLM-RoBERTa: Accuracy: 0.843, F1-score: 0.848, AUC-ROC: 0.908. | J7: The fine-tuned MuRIL transformer achieved the top absolute F1-score (0.863) across all models due to its specialized pre-training on Indian languages and their transliterations, which maps well to code-mixed Romanized Nepali. Within the machine learning architectures, Random Forest achieved the highest F1-score (0.847). | K7: Dataset Constraints: The model remains bound to the restricted size and narrow context of the 2022 local election cycle, which may limit generalizability across broader web domains. Scarcity of Native Language Models: The study lacks optimization using language models natively and exclusively trained on a massive corpus of native Nepali text, as it relies on broad multilingual architectures. Lack of Explainability: The pipeline handles feature blending implicitly, offering no deep architectural interpretability or attention-layer maps to clarify why an input is flagged as hate speech.
A8: 7 | B8: Classifying Sentiments in Nepali Subjective Texts (Thapa & Bal, 2016). | C8: Binary sentiment classification mapping documents into "Positive" or "Negative" categories. | D8: Native Nepali language text written in the Devanagari script. The content consists of subjective, opinionated book and movie reviews crawled from major Nepali news portals (such as eKantipur, Nagarik News, OnlineKhabar, Setopati, Ratopati, and MeroCinema) along with user-generated book reviews from Goodreads. | E8: A manually annotated corpus containing a total of 384 documents, comprising 179 positive reviews and 205 negative reviews. Each document averages roughly 200 words, totaling approximately 76,000 words across the dataset. The validation strategy utilizes a standard 5-fold cross-validation technique. | F8: A clean-up pipeline designed to remove structural online noise, specifically filtering out HTML tags, external URL links, and special symbols like hashtags (#). | G8: Focuses entirely on document-level sentiment mining where each text is treated as a single entity expressing a unified sentiment. The methodology explicitly isolates the impact of stopword filtering by contrasting pipelines that retain all words against pipelines that remove common Nepali grammatical particles and conjunctions (e.g., 'वा', 'अथवा', 'तापनि', 'इत्यादि'). | H8: Feature Spaces: Evaluated four distinct feature representation configurations: Bag-of-Words (BoW), Bag-of-Words with stopwords removed, TF-IDF, and TF-IDF with stopwords removed. Classifiers: Compared three foundational supervised machine learning algorithms: Support Vector Machine (SVM), Multinomial Naive Bayes (MNB), and Logistic Regression. | I8: Multinomial Naive Bayes (Top Performer): With Bag-of-Words: Mean Accuracy: 0.656, Mean F1-Score: 0.672. With TF-IDF: Mean Accuracy: 0.606, Mean F1-Score: 0.734. Logistic Regression: With TF-IDF: Mean Accuracy: 0.606, Mean F1-Score: 0.688. With TF-IDF (Stopwords Removed): Mean Accuracy: 0.584, Mean F1-Score: 0.664. Support Vector Machine: With Bag-of-Words: Mean Accuracy: 0.564, Mean F1-Score: 0.572. | J8: Multinomial Naive Bayes emerged as the superior classifier overall, achieving the highest classification accuracy when paired with standard Bag-of-Words features and yielding the highest absolute F1-score (0.734) when paired with the full TF-IDF vector matrix. | K8: Severe Data Scarcity: The corpus is tiny (only 384 documents), which severely constrains model robustness and prevents the effective adoption of deep learning setups. Coarse N-gram Granularity: The entire pipeline relies strictly on word-level unigram presence or frequency metrics, failing to account for multi-word phrases, complex contextual shifts, or negation patterns. No Morphological Analysis: Despite acknowledging Nepali as a highly inflected, morphologically rich language, the framework does not implement stemming or lemmatization, meaning different inflected forms of the same root word are treated as completely independent features.
A9: 8 | B9: Title: Transformer-Based Deep Learning Models for Sentiment Analysis in Romanized Nepali: A Comparative Investigation of BERT and RoBERTa. Authors: Abhash Pradhananga and Anand Kumar Sah (Department of Electronics and Computer Engineering, Pulchowk Campus, Institute of Engineering, Tribhuvan University, Nepal). | C9: Task: Sentiment Analysis (Text Classification) of consumer-generated digital product reviews. Classification Type: Multi-class classification (Positive, Negative, Neutral). | D9: Data Source: User-generated customer reviews collected from a prominent Nepali e-commerce platform. Language Type: Informal Romanized Nepali (Nepali text written natively using the Latin/Roman alphabet), characterized by significant code-switching with English, lack of standard grammar, and inconsistent phonetic spelling variants. | E9: Dataset Size: 32,817 total manually annotated reviews. Positive Class: 22,880 reviews (69.7%). Negative Class: 8,382 reviews (25.5%). Neutral Class: Remaining balance (4.8%). Splitting Strategy: Evaluated using a 5-fold cross-validation technique to ensure robustness across model comparisons. | F9: Due to the absence of native standard NLP preprocessing tools for Romanized scripts, the authors built a custom normalization pipeline: Noise Removal: Programmatic removal of non-textual elements such as URLs, email configurations, phone numbers, punctuation, and currency markers. Stop Word Elimination: Elimination of standard English stop words combined with a custom-defined corpus of Romanized Nepali functional stop words (e.g., vayo, bhayo, jhan, hai, yo). Phonetic & Base Normalization: Integration of WordNet lemmatization and the Soundex algorithm to cluster phonetic variations of words sharing highly similar pronunciations but distinct spelling structures (e.g., resolving dami and damme to an identical phonetic representation). | G9: Human annotators with Master's degrees established ground truth labels. Inter-Annotator Agreement (IAA): Validated using Cohen's Kappa, achieving a score of 81.32%, confirming high baseline data reliability. Core rule focus relied on resolving script-level inconsistencies by grouping non-standard transliterated tokens before passing them to neural vector spaces. | H9: Traditional Models: Features were engineered using Bag-of-Words (BoW) vector representations and standard text tokenization. Transformer Architectures: Leveraged pre-trained BERT and RoBERTa models, capitalizing on self-attention mechanisms to build contextualized word embeddings dynamically out of the noisy Romanized string structures. | I9: The average model performance compiled via cross-validation highlights: BERT: 79% Accuracy | 0.77 Precision | 0.76 Recall | 0.75 F1-Score. Support Vector Machine (SVM): 75% Accuracy | 0.74 Precision | 0.75 Recall | 0.77 F1-Score. Logistic Regression (LR): 74% Accuracy | 0.76 Precision | 0.75 Recall | 0.75 F1-Score. Naive Bayes (NB): 73% Accuracy | 0.72 Precision | 0.73 Recall | 0.73 F1-Score. | J9: Traditional machine learning classifiers (SVM, Logistic Regression, Naive Bayes) served as the performance baselines. While traditional classifiers proved computationally lean and highly competitive (specifically SVM reaching a 0.77 F1-Score), the Transformer-based BERT model statistically outperformed all baselines in absolute accuracy (79%) by successfully capturing non-linear semantic context across irregular phonetic spellings. | K9: Severe Class Imbalance: The dataset heavily skews toward Positive sentiment (approx. 70%), leaving Neutral (under 5%) and Negative classes vastly underrepresented, causing models to underperform on minority sentiments. Tokenization Breakdown: Standard multilingual BERT tokenizers often split unknown Romanized strings into highly fragmented sub-words or default to [UNK] tokens, losing semantic syntax. Lack of True Transliteration Mapping: Relying heavily on English-centric phonetic rules (like Soundex) fails to capture authentic Indo-Aryan phonetic transitions.
A10: 9 | B10: Profanity and Offensiveness Detection in Nepali Language Using Bi-directional LSTM Models | C10: Multi-task Classification: Task A (Binary Profane), Task B (Binary Offensive), Task C (Three-class: None/Offensive/Profane) | D10: Scraped comments from controversial Facebook posts (celebrities, politicians). Native Devanagari, pure Latin (Romanized), and mixed code-switched scripts. | E10: 1,681 comments (NepSense dataset). Balanced sub-samples used for training: Task A (2,229/class), Task B (1,313/class), Task C (1,313/class). | F10: Romanized Latin script converted to Devanagari using ai4bharat-transliteration. Emojis and punctuation stripped. Stemming and stop-words removed via Nepali_nlp toolkit. | G10: Taboo words define profanity; non-taboo but hurtful words define offensiveness. Two-level keyword matching (166 profane, 720 offensive keys) cross-validated by native speaker. Demographic gender profiles added via voter list names. | H10: Baseline Bi-directional LSTM (Bi-LSTM) sequential model trained on a T4 GPU. Explored standard 256-dimension Vocab Embeddings and Multilingual BERT (mBERT) embeddings. | I10: Task A (Binary Profane): 87.8% Accuracy. Task B (Binary Offensive): 78.2% Accuracy (Low 0.56 Recall). Task C(a) (Multi-class + mBERT): 65% Accuracy. Task C(b) (Multi-class + Vocab): 66.3% Accuracy. | J10: Evaluated Bi-LSTM variants against each other. Proved binary tasks vastly outpace multi-class setups, and simpler Vocab Embeddings match or outperform heavy mBERT embeddings on small data sizes. | K10: Severe low recall (0.56) on purely offensive text due to high contextual ambiguity (e.g., "dog" as an animal vs. an insult). Transliteration errors from user spelling inconsistencies. Vulnerable to evolving generational/Gen-Z slang.
A11: 10 | B11: entiment-Analysis-of-Tourism-Using-Social-Media-Data-in-the-Context-of-Nepal.pdf, Darpan Aryal (July 2025) | C11: Task Definition: Automatically mining, processing, and evaluating online user-generated content (UGC) to assess and predict tourist satisfaction, perceptions, and real-time destination image of Nepal. Classification Type: Supervised, Multi-class Text Classification. Target Classes: Explicitly categorized into a three-way polarity schema: Positive, Neutral, and Negative. | D11: Data Sources: Multi-platform collection tailored to platform roles: Twitter (X): Short-form, immediate, real-time feedback and impressions. TripAdvisor: Dense, in-depth travel reviews focusing on hospitality, accommodation, and service quality. Facebook: Public community group discussions, influencer posts, and comments. Language Type: Multilingual and noisy text. It includes native English, Nepali, and mixed-code Nepali-English (Romanized/transliterated Nepali) text. | E11: Dataset Size: Total Volume: 108,500 data points extracted across three streams. Breakdown: 100,000 Twitter items, 5,000 TripAdvisor reviews, and 3,500 Facebook public comments/posts. Splitting Strategy: Standard machine learning validation split: 80% Training, 10% Validation, and 10% Testing. A separate random 5% subset was extracted for manual verification and human calibration of initial ground truths. | F11: Language Harmonization: Non-English and mixed Nepali content was standardized using the Google Translate API to maintain a uniform English baseline. Noise Cleaning: Structural stripping of URLs, handle mentions, and special symbols. Emojis were systematically translated into their direct textual definitions via the emoji Python library to retain emotional signals. Tokenization & Lemmatization: Handled programmatically utilizing the NLTK and SpaCy engine workflows. Stopword Refinement: Executed customized stopword removal. Domain-specific tourism keywords (such as "trek", "mountain", "guide") were deliberately white-listed and retained because they alter spatial or sentimental context | G11: Initial Distant Supervision: Initial rule-based labeling was automated using the VADER Sentiment Analysis lexicon. VADER Threshold Boundaries: Positive: Compound Score > 0.05 Neutral: Compound Score >= -0.05 and Score <= 0.05$ Negative: Compound Score < -0.05 Validation Anchor: Human judges manually vetted the 5% sample to calibrate the dictionary against colloquial sarcasm, local context, and slang. | H11: Embedding Layer (BERT): Bidirectional Encoder Representations from Transformers (BERT) was deployed to extract dense, deep contextual vector embeddings. This captures word-sense disambiguation based on surrounding text, outperforming traditional static token arrays. Sequence Modeling Layer (BiLSTM): Bidirectional Long Short-Term Memory networks process the sequential word chains bi-directionally (forward and backward) to model sequence-dependent contexts and long-range dependencies. Classification Top: A final Softmax activation layer mapping network outputs directly into the target multiclass distribution probabilities. Framework Stack: Written in Python using the Hugging Face transformers ecosystem and TensorFlow. Optimization was driven by the AdamW optimizer with early stopping metrics active across 5 training epochs. | I11: The hybrid model recorded robust, highly balanced multi-class capabilities across the entire test framework: Accuracy: 89.2% Precision: 88.5% Recall: 87.9% F1-Score: 88.2% | J11: Methodological Comparison: The paper highlights a historical progression away from rigid, early lexicon-only systems (which entirely failed on sarcasm and local nuance) and classic shallow ML classifiers like Naive Bayes and Support Vector Machines (SVM). State-of-the-Art (SOTA) Edge: By contrasting past literature (e.g., Capsule Networks or base descriptive studies), the paper validates that pairing BERT's deep contextual understanding with BiLSTM's temporal sequence handling produces superior stability over basic Transformer baselines when handling messy social media texts. | K11: Linguistic Lossiness: Translating local languages and mixed-code text via basic translate APIs strips out deep native semantic nuances, indigenous phrasing, and contextual emotion. This leaves room to build native, end-to-end multilingual models (like a localized Nepali-BERT variant). Data Selection Bias: Relying strictly on online textual repositories (Twitter, TripAdvisor, Facebook) naturally introduces age and demographic imbalances, ignoring off-grid or non-digital tourist segments. Missing Media Channels: The pipeline ignores visual and multimedia data streams (such as Instagram Reels, YouTube videos, and travel vlogs). Compute Constraints: Hyperparameter optimization was restricted by finite hardware/computational limitations during the training loop. Lack of Granularity: Polarity classification reveals what the sentiment is, but does not isolate specific architectural features. Integrating unsupervised Topic Modeling algorithms (like BERTopic or LDA) alongside sentiment classification would allow systems to automatically map exactly what infrastructure failures (e.g., specific roads or pollution nodes) trigger negative spikes.

Sheet combined_ds
A1: Comments | B1: neutral | C1: hate_speech | D1: threatning | E1: offensive | F1: harassment
